<mujoco model="panda_scene">
  <compiler angle="radian"
    meshdir="../code/.venv/lib/python3.12/site-packages/cmeel.prefix/share/example-robot-data/robots/panda_description/meshes/collision"
    balanceinertia="true" />

  <option timestep="0.02" integrator="RK4" />

  <asset>
    <mesh name="link0" file="link0.stl" />
    <mesh name="link1" file="link1.stl" />
    <mesh name="link2" file="link2.stl" />
    <mesh name="link3" file="link3.stl" />
    <mesh name="link4" file="link4.stl" />
    <mesh name="link5" file="link5.stl" />
    <mesh name="link6" file="link6.stl" />
    <mesh name="link7" file="link7.stl" />
    <mesh name="hand" file="hand.stl" />
  </asset>

  <worldbody>
    <light pos="0 0 2" dir="0 0 -1" diffuse="0.8 0.8 0.8" />
    <geom name="floor" type="plane" size="2 2 0.1" pos="0 0 0" rgba="0.8 0.8 0.8 1" />

    <!-- Panda base (fixed to world) -->
    <body name="panda_link0" pos="0 0 0">
      <geom type="mesh" mesh="link0" />

      <body name="panda_link1" pos="0 0 0.333">
        <inertial pos="0.003875 0.002081 -0.04762" quat="0.711549 0.00634377 -0.0131124 0.702485"
          mass="4.97068" diaginertia="0.707137 0.703435 0.00852456" />
        <joint name="panda_joint1" pos="0 0 0" axis="0 0 1" range="-2.8973 2.8973" damping="0.003" />
        <geom type="mesh" mesh="link1" />

        <body name="panda_link2" quat="0.707107 -0.707107 0 0">
          <inertial pos="-0.003141 -0.02872 0.003495" quat="-0.168175 0.828366 -0.122878 0.520027"
            mass="0.646926" diaginertia="0.0310326 0.0283001 0.00273425" />
          <joint name="panda_joint2" pos="0 0 0" axis="0 0 1" range="-1.7628 1.7628" damping="0.003" />
          <geom type="mesh" mesh="link2" />

          <body name="panda_link3" pos="0 -0.316 0" quat="0.707107 0.707107 0 0">
            <inertial pos="0.027518 0.039252 -0.066502"
              quat="0.662769 -0.00678331 0.252053 0.705096" mass="3.2286"
              diaginertia="0.0415014 0.0414793 0.00124635" />
            <joint name="panda_joint3" pos="0 0 0" axis="0 0 1" range="-2.8973 2.8973"
              damping="0.003" />
            <geom type="mesh" mesh="link3" />

            <body name="panda_link4" pos="0.0825 0 0" quat="0.707107 0.707107 0 0">
              <inertial pos="-0.05317 0.104419 0.027454" quat="0.65058 0.529822 -0.0962034 0.535518"
                mass="3.5879" diaginertia="0.0349596 0.0281483 0.0106201" />
              <joint name="panda_joint4" pos="0 0 0" axis="0 0 1" range="-3.0718 -0.0698"
                damping="0.003" />
              <geom type="mesh" mesh="link4" />

              <body name="panda_link5" pos="-0.0825 0.384 0" quat="0.707107 -0.707107 0 0">
                <inertial pos="-0.011953 0.041065 -0.038437"
                  quat="0.987313 -0.0121954 0.0719187 -0.141037" mass="1.22595"
                  diaginertia="0.0367625 0.0288531 0.00803437" />
                <joint name="panda_joint5" pos="0 0 0" axis="0 0 1" range="-2.8973 2.8973"
                  damping="0.003" />
                <geom type="mesh" mesh="link5" />

                <body name="panda_link6" quat="0.707107 0.707107 0 0">
                  <inertial pos="0.060149 -0.014117 -0.010517"
                    quat="0.101075 0.59332 0.0287227 0.798079" mass="1.66656"
                    diaginertia="0.00584276 0.00431037 0.00159787" />
                  <joint name="panda_joint6" pos="0 0 0" axis="0 0 1" range="-0.0175 3.7525"
                    damping="0.003" />
                  <geom type="mesh" mesh="link6" />

                  <body name="panda_link7" pos="0.088 0 0" quat="0.707107 0.707107 0 0">
                    <inertial pos="0.0535956 -0.00213401 0.045858"
                      quat="0.594329 -0.0303333 0.0970674 0.797766" mass="1.46552"
                      diaginertia="0.0155969 0.0137507 0.00943568" />
                    <joint name="panda_joint7" pos="0 0 0" axis="0 0 1" range="-2.8973 2.8973"
                      damping="0.003" />
                    <geom type="mesh" mesh="link7" />
                    <geom pos="0 0 0.107" quat="0.92388 0 0 -0.382683" type="mesh" mesh="hand" />
                    <body name="panda_leftfinger" pos="0 0 0.1654" quat="0.92388 0 0 -0.382683">
                      <inertial pos="0 0 0" mass="0.015" diaginertia="2.375e-06 2.375e-06 7.5e-07" />
                      <joint name="panda_finger_joint1" pos="0 0 0" axis="0 1 0" type="slide"
                        range="0 0.04" actuatorfrcrange="-100 100" damping="0.3" />
                      <geom size="0.011 0.0075 0.01" pos="0 0.0185 0.011" type="box" />
                      <geom size="0.011 0.0044 0.0019" pos="0 0.0068 0.0022" type="box" />
                      <geom size="0.00875 0.0035 0.01175" pos="0 0.0159 0.02835"
                        quat="0.965926 0.258819 0 0" type="box" />
                      <geom size="0.00875 0.0076 0.00925" pos="0 0.00758 0.04525" type="box" />
                    </body>
                    <body name="panda_rightfinger" pos="0 0 0.1654" quat="0.92388 0 0 -0.382683">
                      <inertial pos="0 0 0" mass="0.015" diaginertia="2.375e-06 2.375e-06 7.5e-07" />
                      <joint name="panda_finger_joint2" pos="0 0 0" axis="0 -1 0" type="slide"
                        range="0 0.04" actuatorfrcrange="-100 100" damping="0.3" />
                      <geom size="0.011 0.0075 0.01" pos="0 -0.0185 0.011" type="box" />
                      <geom size="0.011 0.0044 0.0019" pos="0 -0.0068 0.0022" type="box" />
                      <geom size="0.00875 0.0035 0.01175" pos="0 -0.0159 0.02835"
                        quat="0.965926 -0.258819 0 0" type="box" />
                      <geom size="0.00875 0.0076 0.00925" pos="0 -0.00758 0.04525" type="box" />
                    </body>
                    <!-- End-effector site (panda_hand_tcp equivalent) -->
                    <site name="ee_site" pos="0 0 0.2105" quat="0.92388 0 0 -0.382683" size="0.01"
                      rgba="1 0 0 0.5" />
                  </body>
                </body>
              </body>
            </body>
          </body>
        </body>
      </body>
    </body>

    <!-- Obstacle spheres (positions set by env at runtime via mj_data.geom_xpos) -->
    <body name="obstacle0" pos="0.5 0.1 0.5" mocap="true">
      <geom name="obs0" type="sphere" size="0.1" rgba="1 0 0 0.5" contype="1" conaffinity="1" />
    </body>
    <body name="obstacle1" pos="0.5 -0.1 0.4" mocap="true">
      <geom name="obs1" type="sphere" size="0.1" rgba="1 0 0 0.5" contype="1" conaffinity="1" />
    </body>
    <body name="obstacle2" pos="0.4 0.0 0.6" mocap="true">
      <geom name="obs2" type="sphere" size="0.1" rgba="1 0 0 0.5" contype="1" conaffinity="1" />
    </body>
  </worldbody>

  <keyframe>
    <key name="home" qpos="0 0 0 -1.5708 0 1.5708 0.7854 0 0" />
  </keyframe>

  <!-- Velocity actuators for 7 arm joints -->
  <actuator>
    <velocity name="act_j1" joint="panda_joint1" kv="10" forcerange="-87 87" />
    <velocity name="act_j2" joint="panda_joint2" kv="10" forcerange="-87 87" />
    <velocity name="act_j3" joint="panda_joint3" kv="10" forcerange="-87 87" />
    <velocity name="act_j4" joint="panda_joint4" kv="10" forcerange="-87 87" />
    <velocity name="act_j5" joint="panda_joint5" kv="10" forcerange="-12 12" />
    <velocity name="act_j6" joint="panda_joint6" kv="10" forcerange="-12 12" />
    <velocity name="act_j7" joint="panda_joint7" kv="10" forcerange="-12 12" />
  </actuator>
</mujoco>